2024-04-20 17:24:31,193 - INFO - Inicio de sesión exitoso para el usuario: sergionvte11@gmail.com
2024-04-20 17:25:31,642 - INFO - Inicio de sesión exitoso para el usuario: sergionvte11@gmail.com
2024-04-20 17:28:21,848 - INFO - Inicio de sesión exitoso para el usuario: dario.prro@gmail.com
2024-04-20 17:39:51,777 - INFO - /Users/sergionvte/Documents/Modular/moviematch/webapp/views.py changed, reloading.
2024-04-20 17:41:05,838 - INFO - /Users/sergionvte/Documents/Modular/moviematch/webapp/views.py changed, reloading.
2024-04-20 17:42:15,952 - ERROR - Internal Server Error: /
Traceback (most recent call last):
  File "/Users/sergionvte/Documents/Modular/venv/lib/python3.9/site-packages/django/core/handlers/exception.py", line 55, in inner
    response = get_response(request)
  File "/Users/sergionvte/Documents/Modular/venv/lib/python3.9/site-packages/django/core/handlers/base.py", line 197, in _get_response
    response = wrapped_callback(request, *callback_args, **callback_kwargs)
  File "/Users/sergionvte/Documents/Modular/moviematch/webapp/views.py", line 28, in index
    return render(request, 'index.html')
  File "/Users/sergionvte/Documents/Modular/venv/lib/python3.9/site-packages/django/shortcuts.py", line 24, in render
    content = loader.render_to_string(template_name, context, request, using=using)
  File "/Users/sergionvte/Documents/Modular/venv/lib/python3.9/site-packages/django/template/loader.py", line 61, in render_to_string
    template = get_template(template_name, using=using)
  File "/Users/sergionvte/Documents/Modular/venv/lib/python3.9/site-packages/django/template/loader.py", line 15, in get_template
    return engine.get_template(template_name)
  File "/Users/sergionvte/Documents/Modular/venv/lib/python3.9/site-packages/django/template/backends/django.py", line 33, in get_template
    return Template(self.engine.get_template(template_name), self)
  File "/Users/sergionvte/Documents/Modular/venv/lib/python3.9/site-packages/django/template/engine.py", line 175, in get_template
    template, origin = self.find_template(template_name)
  File "/Users/sergionvte/Documents/Modular/venv/lib/python3.9/site-packages/django/template/engine.py", line 157, in find_template
    template = loader.get_template(name, skip=skip)
  File "/Users/sergionvte/Documents/Modular/venv/lib/python3.9/site-packages/django/template/loaders/cached.py", line 57, in get_template
    template = super().get_template(template_name, skip)
  File "/Users/sergionvte/Documents/Modular/venv/lib/python3.9/site-packages/django/template/loaders/base.py", line 28, in get_template
    return Template(
  File "/Users/sergionvte/Documents/Modular/venv/lib/python3.9/site-packages/django/template/base.py", line 154, in __init__
    self.nodelist = self.compile_nodelist()
  File "/Users/sergionvte/Documents/Modular/venv/lib/python3.9/site-packages/django/template/base.py", line 200, in compile_nodelist
    return parser.parse()
  File "/Users/sergionvte/Documents/Modular/venv/lib/python3.9/site-packages/django/template/base.py", line 513, in parse
    raise self.error(token, e)
  File "/Users/sergionvte/Documents/Modular/venv/lib/python3.9/site-packages/django/template/base.py", line 511, in parse
    compiled_result = compile_func(self, token)
  File "/Users/sergionvte/Documents/Modular/venv/lib/python3.9/site-packages/django/template/loader_tags.py", line 293, in do_extends
    nodelist = parser.parse()
  File "/Users/sergionvte/Documents/Modular/venv/lib/python3.9/site-packages/django/template/base.py", line 513, in parse
    raise self.error(token, e)
  File "/Users/sergionvte/Documents/Modular/venv/lib/python3.9/site-packages/django/template/base.py", line 511, in parse
    compiled_result = compile_func(self, token)
  File "/Users/sergionvte/Documents/Modular/venv/lib/python3.9/site-packages/django/template/loader_tags.py", line 232, in do_block
    nodelist = parser.parse(("endblock",))
  File "/Users/sergionvte/Documents/Modular/venv/lib/python3.9/site-packages/django/template/base.py", line 513, in parse
    raise self.error(token, e)
  File "/Users/sergionvte/Documents/Modular/venv/lib/python3.9/site-packages/django/template/base.py", line 511, in parse
    compiled_result = compile_func(self, token)
  File "/Users/sergionvte/Documents/Modular/venv/lib/python3.9/site-packages/django/template/loader_tags.py", line 293, in do_extends
    nodelist = parser.parse()
  File "/Users/sergionvte/Documents/Modular/venv/lib/python3.9/site-packages/django/template/base.py", line 513, in parse
    raise self.error(token, e)
  File "/Users/sergionvte/Documents/Modular/venv/lib/python3.9/site-packages/django/template/base.py", line 511, in parse
    compiled_result = compile_func(self, token)
  File "/Users/sergionvte/Documents/Modular/venv/lib/python3.9/site-packages/django/template/loader_tags.py", line 226, in do_block
    raise TemplateSyntaxError(
django.template.exceptions.TemplateSyntaxError: 'block' tag with name 'title' appears more than once
2024-04-20 17:42:16,084 - WARNING - Not Found: /favicon.ico
2024-04-20 17:43:09,022 - ERROR - Internal Server Error: /
Traceback (most recent call last):
  File "/Users/sergionvte/Documents/Modular/venv/lib/python3.9/site-packages/django/core/handlers/exception.py", line 55, in inner
    response = get_response(request)
  File "/Users/sergionvte/Documents/Modular/venv/lib/python3.9/site-packages/django/core/handlers/base.py", line 197, in _get_response
    response = wrapped_callback(request, *callback_args, **callback_kwargs)
  File "/Users/sergionvte/Documents/Modular/moviematch/webapp/views.py", line 28, in index
    return render(request, 'index.html')
  File "/Users/sergionvte/Documents/Modular/venv/lib/python3.9/site-packages/django/shortcuts.py", line 24, in render
    content = loader.render_to_string(template_name, context, request, using=using)
  File "/Users/sergionvte/Documents/Modular/venv/lib/python3.9/site-packages/django/template/loader.py", line 61, in render_to_string
    template = get_template(template_name, using=using)
  File "/Users/sergionvte/Documents/Modular/venv/lib/python3.9/site-packages/django/template/loader.py", line 15, in get_template
    return engine.get_template(template_name)
  File "/Users/sergionvte/Documents/Modular/venv/lib/python3.9/site-packages/django/template/backends/django.py", line 33, in get_template
    return Template(self.engine.get_template(template_name), self)
  File "/Users/sergionvte/Documents/Modular/venv/lib/python3.9/site-packages/django/template/engine.py", line 175, in get_template
    template, origin = self.find_template(template_name)
  File "/Users/sergionvte/Documents/Modular/venv/lib/python3.9/site-packages/django/template/engine.py", line 157, in find_template
    template = loader.get_template(name, skip=skip)
  File "/Users/sergionvte/Documents/Modular/venv/lib/python3.9/site-packages/django/template/loaders/cached.py", line 57, in get_template
    template = super().get_template(template_name, skip)
  File "/Users/sergionvte/Documents/Modular/venv/lib/python3.9/site-packages/django/template/loaders/base.py", line 28, in get_template
    return Template(
  File "/Users/sergionvte/Documents/Modular/venv/lib/python3.9/site-packages/django/template/base.py", line 154, in __init__
    self.nodelist = self.compile_nodelist()
  File "/Users/sergionvte/Documents/Modular/venv/lib/python3.9/site-packages/django/template/base.py", line 200, in compile_nodelist
    return parser.parse()
  File "/Users/sergionvte/Documents/Modular/venv/lib/python3.9/site-packages/django/template/base.py", line 513, in parse
    raise self.error(token, e)
  File "/Users/sergionvte/Documents/Modular/venv/lib/python3.9/site-packages/django/template/base.py", line 511, in parse
    compiled_result = compile_func(self, token)
  File "/Users/sergionvte/Documents/Modular/venv/lib/python3.9/site-packages/django/template/loader_tags.py", line 293, in do_extends
    nodelist = parser.parse()
  File "/Users/sergionvte/Documents/Modular/venv/lib/python3.9/site-packages/django/template/base.py", line 513, in parse
    raise self.error(token, e)
  File "/Users/sergionvte/Documents/Modular/venv/lib/python3.9/site-packages/django/template/base.py", line 511, in parse
    compiled_result = compile_func(self, token)
  File "/Users/sergionvte/Documents/Modular/venv/lib/python3.9/site-packages/django/template/loader_tags.py", line 232, in do_block
    nodelist = parser.parse(("endblock",))
  File "/Users/sergionvte/Documents/Modular/venv/lib/python3.9/site-packages/django/template/base.py", line 513, in parse
    raise self.error(token, e)
  File "/Users/sergionvte/Documents/Modular/venv/lib/python3.9/site-packages/django/template/base.py", line 511, in parse
    compiled_result = compile_func(self, token)
  File "/Users/sergionvte/Documents/Modular/venv/lib/python3.9/site-packages/django/template/loader_tags.py", line 293, in do_extends
    nodelist = parser.parse()
  File "/Users/sergionvte/Documents/Modular/venv/lib/python3.9/site-packages/django/template/base.py", line 513, in parse
    raise self.error(token, e)
  File "/Users/sergionvte/Documents/Modular/venv/lib/python3.9/site-packages/django/template/base.py", line 511, in parse
    compiled_result = compile_func(self, token)
  File "/Users/sergionvte/Documents/Modular/venv/lib/python3.9/site-packages/django/template/loader_tags.py", line 226, in do_block
    raise TemplateSyntaxError(
django.template.exceptions.TemplateSyntaxError: 'block' tag with name 'title' appears more than once
2024-04-20 17:43:11,348 - ERROR - Internal Server Error: /
Traceback (most recent call last):
  File "/Users/sergionvte/Documents/Modular/venv/lib/python3.9/site-packages/django/core/handlers/exception.py", line 55, in inner
    response = get_response(request)
  File "/Users/sergionvte/Documents/Modular/venv/lib/python3.9/site-packages/django/core/handlers/base.py", line 197, in _get_response
    response = wrapped_callback(request, *callback_args, **callback_kwargs)
  File "/Users/sergionvte/Documents/Modular/moviematch/webapp/views.py", line 28, in index
    return render(request, 'index.html')
  File "/Users/sergionvte/Documents/Modular/venv/lib/python3.9/site-packages/django/shortcuts.py", line 24, in render
    content = loader.render_to_string(template_name, context, request, using=using)
  File "/Users/sergionvte/Documents/Modular/venv/lib/python3.9/site-packages/django/template/loader.py", line 61, in render_to_string
    template = get_template(template_name, using=using)
  File "/Users/sergionvte/Documents/Modular/venv/lib/python3.9/site-packages/django/template/loader.py", line 15, in get_template
    return engine.get_template(template_name)
  File "/Users/sergionvte/Documents/Modular/venv/lib/python3.9/site-packages/django/template/backends/django.py", line 33, in get_template
    return Template(self.engine.get_template(template_name), self)
  File "/Users/sergionvte/Documents/Modular/venv/lib/python3.9/site-packages/django/template/engine.py", line 175, in get_template
    template, origin = self.find_template(template_name)
  File "/Users/sergionvte/Documents/Modular/venv/lib/python3.9/site-packages/django/template/engine.py", line 157, in find_template
    template = loader.get_template(name, skip=skip)
  File "/Users/sergionvte/Documents/Modular/venv/lib/python3.9/site-packages/django/template/loaders/cached.py", line 57, in get_template
    template = super().get_template(template_name, skip)
  File "/Users/sergionvte/Documents/Modular/venv/lib/python3.9/site-packages/django/template/loaders/base.py", line 28, in get_template
    return Template(
  File "/Users/sergionvte/Documents/Modular/venv/lib/python3.9/site-packages/django/template/base.py", line 154, in __init__
    self.nodelist = self.compile_nodelist()
  File "/Users/sergionvte/Documents/Modular/venv/lib/python3.9/site-packages/django/template/base.py", line 200, in compile_nodelist
    return parser.parse()
  File "/Users/sergionvte/Documents/Modular/venv/lib/python3.9/site-packages/django/template/base.py", line 513, in parse
    raise self.error(token, e)
  File "/Users/sergionvte/Documents/Modular/venv/lib/python3.9/site-packages/django/template/base.py", line 511, in parse
    compiled_result = compile_func(self, token)
  File "/Users/sergionvte/Documents/Modular/venv/lib/python3.9/site-packages/django/template/loader_tags.py", line 293, in do_extends
    nodelist = parser.parse()
  File "/Users/sergionvte/Documents/Modular/venv/lib/python3.9/site-packages/django/template/base.py", line 513, in parse
    raise self.error(token, e)
  File "/Users/sergionvte/Documents/Modular/venv/lib/python3.9/site-packages/django/template/base.py", line 511, in parse
    compiled_result = compile_func(self, token)
  File "/Users/sergionvte/Documents/Modular/venv/lib/python3.9/site-packages/django/template/loader_tags.py", line 232, in do_block
    nodelist = parser.parse(("endblock",))
  File "/Users/sergionvte/Documents/Modular/venv/lib/python3.9/site-packages/django/template/base.py", line 513, in parse
    raise self.error(token, e)
  File "/Users/sergionvte/Documents/Modular/venv/lib/python3.9/site-packages/django/template/base.py", line 511, in parse
    compiled_result = compile_func(self, token)
  File "/Users/sergionvte/Documents/Modular/venv/lib/python3.9/site-packages/django/template/loader_tags.py", line 293, in do_extends
    nodelist = parser.parse()
  File "/Users/sergionvte/Documents/Modular/venv/lib/python3.9/site-packages/django/template/base.py", line 513, in parse
    raise self.error(token, e)
  File "/Users/sergionvte/Documents/Modular/venv/lib/python3.9/site-packages/django/template/base.py", line 511, in parse
    compiled_result = compile_func(self, token)
  File "/Users/sergionvte/Documents/Modular/venv/lib/python3.9/site-packages/django/template/loader_tags.py", line 226, in do_block
    raise TemplateSyntaxError(
django.template.exceptions.TemplateSyntaxError: 'block' tag with name 'title' appears more than once
2024-04-20 17:43:28,467 - ERROR - Internal Server Error: /
Traceback (most recent call last):
  File "/Users/sergionvte/Documents/Modular/venv/lib/python3.9/site-packages/django/core/handlers/exception.py", line 55, in inner
    response = get_response(request)
  File "/Users/sergionvte/Documents/Modular/venv/lib/python3.9/site-packages/django/core/handlers/base.py", line 197, in _get_response
    response = wrapped_callback(request, *callback_args, **callback_kwargs)
  File "/Users/sergionvte/Documents/Modular/moviematch/webapp/views.py", line 28, in index
    return render(request, 'index.html')
  File "/Users/sergionvte/Documents/Modular/venv/lib/python3.9/site-packages/django/shortcuts.py", line 24, in render
    content = loader.render_to_string(template_name, context, request, using=using)
  File "/Users/sergionvte/Documents/Modular/venv/lib/python3.9/site-packages/django/template/loader.py", line 61, in render_to_string
    template = get_template(template_name, using=using)
  File "/Users/sergionvte/Documents/Modular/venv/lib/python3.9/site-packages/django/template/loader.py", line 15, in get_template
    return engine.get_template(template_name)
  File "/Users/sergionvte/Documents/Modular/venv/lib/python3.9/site-packages/django/template/backends/django.py", line 33, in get_template
    return Template(self.engine.get_template(template_name), self)
  File "/Users/sergionvte/Documents/Modular/venv/lib/python3.9/site-packages/django/template/engine.py", line 175, in get_template
    template, origin = self.find_template(template_name)
  File "/Users/sergionvte/Documents/Modular/venv/lib/python3.9/site-packages/django/template/engine.py", line 157, in find_template
    template = loader.get_template(name, skip=skip)
  File "/Users/sergionvte/Documents/Modular/venv/lib/python3.9/site-packages/django/template/loaders/cached.py", line 57, in get_template
    template = super().get_template(template_name, skip)
  File "/Users/sergionvte/Documents/Modular/venv/lib/python3.9/site-packages/django/template/loaders/base.py", line 28, in get_template
    return Template(
  File "/Users/sergionvte/Documents/Modular/venv/lib/python3.9/site-packages/django/template/base.py", line 154, in __init__
    self.nodelist = self.compile_nodelist()
  File "/Users/sergionvte/Documents/Modular/venv/lib/python3.9/site-packages/django/template/base.py", line 200, in compile_nodelist
    return parser.parse()
  File "/Users/sergionvte/Documents/Modular/venv/lib/python3.9/site-packages/django/template/base.py", line 513, in parse
    raise self.error(token, e)
  File "/Users/sergionvte/Documents/Modular/venv/lib/python3.9/site-packages/django/template/base.py", line 511, in parse
    compiled_result = compile_func(self, token)
  File "/Users/sergionvte/Documents/Modular/venv/lib/python3.9/site-packages/django/template/loader_tags.py", line 293, in do_extends
    nodelist = parser.parse()
  File "/Users/sergionvte/Documents/Modular/venv/lib/python3.9/site-packages/django/template/base.py", line 513, in parse
    raise self.error(token, e)
  File "/Users/sergionvte/Documents/Modular/venv/lib/python3.9/site-packages/django/template/base.py", line 511, in parse
    compiled_result = compile_func(self, token)
  File "/Users/sergionvte/Documents/Modular/venv/lib/python3.9/site-packages/django/template/loader_tags.py", line 232, in do_block
    nodelist = parser.parse(("endblock",))
  File "/Users/sergionvte/Documents/Modular/venv/lib/python3.9/site-packages/django/template/base.py", line 513, in parse
    raise self.error(token, e)
  File "/Users/sergionvte/Documents/Modular/venv/lib/python3.9/site-packages/django/template/base.py", line 511, in parse
    compiled_result = compile_func(self, token)
  File "/Users/sergionvte/Documents/Modular/venv/lib/python3.9/site-packages/django/template/loader_tags.py", line 293, in do_extends
    nodelist = parser.parse()
  File "/Users/sergionvte/Documents/Modular/venv/lib/python3.9/site-packages/django/template/base.py", line 513, in parse
    raise self.error(token, e)
  File "/Users/sergionvte/Documents/Modular/venv/lib/python3.9/site-packages/django/template/base.py", line 511, in parse
    compiled_result = compile_func(self, token)
  File "/Users/sergionvte/Documents/Modular/venv/lib/python3.9/site-packages/django/template/loader_tags.py", line 226, in do_block
    raise TemplateSyntaxError(
django.template.exceptions.TemplateSyntaxError: 'block' tag with name 'content' appears more than once
2024-04-20 17:53:40,958 - ERROR - Internal Server Error: /
Traceback (most recent call last):
  File "/Users/sergionvte/Documents/Modular/venv/lib/python3.9/site-packages/django/template/base.py", line 505, in parse
    compile_func = self.tags[command]
KeyError: 'endblock'

During handling of the above exception, another exception occurred:

Traceback (most recent call last):
  File "/Users/sergionvte/Documents/Modular/venv/lib/python3.9/site-packages/django/core/handlers/exception.py", line 55, in inner
    response = get_response(request)
  File "/Users/sergionvte/Documents/Modular/venv/lib/python3.9/site-packages/django/core/handlers/base.py", line 197, in _get_response
    response = wrapped_callback(request, *callback_args, **callback_kwargs)
  File "/Users/sergionvte/Documents/Modular/moviematch/webapp/views.py", line 28, in index
    return render(request, 'index.html')
  File "/Users/sergionvte/Documents/Modular/venv/lib/python3.9/site-packages/django/shortcuts.py", line 24, in render
    content = loader.render_to_string(template_name, context, request, using=using)
  File "/Users/sergionvte/Documents/Modular/venv/lib/python3.9/site-packages/django/template/loader.py", line 61, in render_to_string
    template = get_template(template_name, using=using)
  File "/Users/sergionvte/Documents/Modular/venv/lib/python3.9/site-packages/django/template/loader.py", line 15, in get_template
    return engine.get_template(template_name)
  File "/Users/sergionvte/Documents/Modular/venv/lib/python3.9/site-packages/django/template/backends/django.py", line 33, in get_template
    return Template(self.engine.get_template(template_name), self)
  File "/Users/sergionvte/Documents/Modular/venv/lib/python3.9/site-packages/django/template/engine.py", line 175, in get_template
    template, origin = self.find_template(template_name)
  File "/Users/sergionvte/Documents/Modular/venv/lib/python3.9/site-packages/django/template/engine.py", line 157, in find_template
    template = loader.get_template(name, skip=skip)
  File "/Users/sergionvte/Documents/Modular/venv/lib/python3.9/site-packages/django/template/loaders/cached.py", line 57, in get_template
    template = super().get_template(template_name, skip)
  File "/Users/sergionvte/Documents/Modular/venv/lib/python3.9/site-packages/django/template/loaders/base.py", line 28, in get_template
    return Template(
  File "/Users/sergionvte/Documents/Modular/venv/lib/python3.9/site-packages/django/template/base.py", line 154, in __init__
    self.nodelist = self.compile_nodelist()
  File "/Users/sergionvte/Documents/Modular/venv/lib/python3.9/site-packages/django/template/base.py", line 200, in compile_nodelist
    return parser.parse()
  File "/Users/sergionvte/Documents/Modular/venv/lib/python3.9/site-packages/django/template/base.py", line 513, in parse
    raise self.error(token, e)
  File "/Users/sergionvte/Documents/Modular/venv/lib/python3.9/site-packages/django/template/base.py", line 511, in parse
    compiled_result = compile_func(self, token)
  File "/Users/sergionvte/Documents/Modular/venv/lib/python3.9/site-packages/django/template/loader_tags.py", line 293, in do_extends
    nodelist = parser.parse()
  File "/Users/sergionvte/Documents/Modular/venv/lib/python3.9/site-packages/django/template/base.py", line 513, in parse
    raise self.error(token, e)
  File "/Users/sergionvte/Documents/Modular/venv/lib/python3.9/site-packages/django/template/base.py", line 511, in parse
    compiled_result = compile_func(self, token)
  File "/Users/sergionvte/Documents/Modular/venv/lib/python3.9/site-packages/django/template/loader_tags.py", line 232, in do_block
    nodelist = parser.parse(("endblock",))
  File "/Users/sergionvte/Documents/Modular/venv/lib/python3.9/site-packages/django/template/base.py", line 513, in parse
    raise self.error(token, e)
  File "/Users/sergionvte/Documents/Modular/venv/lib/python3.9/site-packages/django/template/base.py", line 511, in parse
    compiled_result = compile_func(self, token)
  File "/Users/sergionvte/Documents/Modular/venv/lib/python3.9/site-packages/django/template/defaulttags.py", line 967, in do_if
    nodelist = parser.parse(("endif",))
  File "/Users/sergionvte/Documents/Modular/venv/lib/python3.9/site-packages/django/template/base.py", line 507, in parse
    self.invalid_block_tag(token, command, parse_until)
  File "/Users/sergionvte/Documents/Modular/venv/lib/python3.9/site-packages/django/template/base.py", line 558, in invalid_block_tag
    raise self.error(
django.template.exceptions.TemplateSyntaxError: Invalid block tag on line 15: 'endblock', expected 'endif'. Did you forget to register or load this tag?
2024-04-20 17:57:29,667 - INFO - Inicio de sesión exitoso para el usuario: sergionvte11@gmail.com
2024-04-20 17:58:15,499 - ERROR - Internal Server Error: /
Traceback (most recent call last):
  File "/Users/sergionvte/Documents/Modular/venv/lib/python3.9/site-packages/django/template/base.py", line 505, in parse
    compile_func = self.tags[command]
KeyError: 'endblock'

During handling of the above exception, another exception occurred:

Traceback (most recent call last):
  File "/Users/sergionvte/Documents/Modular/venv/lib/python3.9/site-packages/django/core/handlers/exception.py", line 55, in inner
    response = get_response(request)
  File "/Users/sergionvte/Documents/Modular/venv/lib/python3.9/site-packages/django/core/handlers/base.py", line 197, in _get_response
    response = wrapped_callback(request, *callback_args, **callback_kwargs)
  File "/Users/sergionvte/Documents/Modular/moviematch/webapp/views.py", line 28, in index
    return render(request, 'index.html')
  File "/Users/sergionvte/Documents/Modular/venv/lib/python3.9/site-packages/django/shortcuts.py", line 24, in render
    content = loader.render_to_string(template_name, context, request, using=using)
  File "/Users/sergionvte/Documents/Modular/venv/lib/python3.9/site-packages/django/template/loader.py", line 61, in render_to_string
    template = get_template(template_name, using=using)
  File "/Users/sergionvte/Documents/Modular/venv/lib/python3.9/site-packages/django/template/loader.py", line 15, in get_template
    return engine.get_template(template_name)
  File "/Users/sergionvte/Documents/Modular/venv/lib/python3.9/site-packages/django/template/backends/django.py", line 33, in get_template
    return Template(self.engine.get_template(template_name), self)
  File "/Users/sergionvte/Documents/Modular/venv/lib/python3.9/site-packages/django/template/engine.py", line 175, in get_template
    template, origin = self.find_template(template_name)
  File "/Users/sergionvte/Documents/Modular/venv/lib/python3.9/site-packages/django/template/engine.py", line 157, in find_template
    template = loader.get_template(name, skip=skip)
  File "/Users/sergionvte/Documents/Modular/venv/lib/python3.9/site-packages/django/template/loaders/cached.py", line 57, in get_template
    template = super().get_template(template_name, skip)
  File "/Users/sergionvte/Documents/Modular/venv/lib/python3.9/site-packages/django/template/loaders/base.py", line 28, in get_template
    return Template(
  File "/Users/sergionvte/Documents/Modular/venv/lib/python3.9/site-packages/django/template/base.py", line 154, in __init__
    self.nodelist = self.compile_nodelist()
  File "/Users/sergionvte/Documents/Modular/venv/lib/python3.9/site-packages/django/template/base.py", line 200, in compile_nodelist
    return parser.parse()
  File "/Users/sergionvte/Documents/Modular/venv/lib/python3.9/site-packages/django/template/base.py", line 513, in parse
    raise self.error(token, e)
  File "/Users/sergionvte/Documents/Modular/venv/lib/python3.9/site-packages/django/template/base.py", line 511, in parse
    compiled_result = compile_func(self, token)
  File "/Users/sergionvte/Documents/Modular/venv/lib/python3.9/site-packages/django/template/loader_tags.py", line 293, in do_extends
    nodelist = parser.parse()
  File "/Users/sergionvte/Documents/Modular/venv/lib/python3.9/site-packages/django/template/base.py", line 513, in parse
    raise self.error(token, e)
  File "/Users/sergionvte/Documents/Modular/venv/lib/python3.9/site-packages/django/template/base.py", line 511, in parse
    compiled_result = compile_func(self, token)
  File "/Users/sergionvte/Documents/Modular/venv/lib/python3.9/site-packages/django/template/loader_tags.py", line 232, in do_block
    nodelist = parser.parse(("endblock",))
  File "/Users/sergionvte/Documents/Modular/venv/lib/python3.9/site-packages/django/template/base.py", line 513, in parse
    raise self.error(token, e)
  File "/Users/sergionvte/Documents/Modular/venv/lib/python3.9/site-packages/django/template/base.py", line 511, in parse
    compiled_result = compile_func(self, token)
  File "/Users/sergionvte/Documents/Modular/venv/lib/python3.9/site-packages/django/template/defaulttags.py", line 967, in do_if
    nodelist = parser.parse(("endif",))
  File "/Users/sergionvte/Documents/Modular/venv/lib/python3.9/site-packages/django/template/base.py", line 507, in parse
    self.invalid_block_tag(token, command, parse_until)
  File "/Users/sergionvte/Documents/Modular/venv/lib/python3.9/site-packages/django/template/base.py", line 558, in invalid_block_tag
    raise self.error(
django.template.exceptions.TemplateSyntaxError: Invalid block tag on line 86: 'endblock', expected 'endif'. Did you forget to register or load this tag?
2024-04-20 18:02:12,940 - INFO - /Users/sergionvte/Documents/Modular/moviematch/webapp/views.py changed, reloading.
2024-04-20 18:03:21,572 - INFO - /Users/sergionvte/Documents/Modular/moviematch/webapp/views.py changed, reloading.
2024-04-20 18:03:53,632 - INFO - /Users/sergionvte/Documents/Modular/moviematch/webapp/views.py changed, reloading.
2024-04-20 18:05:39,670 - INFO - /Users/sergionvte/Documents/Modular/moviematch/webapp/views.py changed, reloading.
2024-04-20 18:08:46,222 - INFO - /Users/sergionvte/Documents/Modular/moviematch/webapp/views.py changed, reloading.
2024-04-20 18:08:52,710 - INFO - /Users/sergionvte/Documents/Modular/moviematch/webapp/views.py changed, reloading.
2024-04-20 18:10:14,885 - INFO - /Users/sergionvte/Documents/Modular/moviematch/webapp/views.py changed, reloading.
2024-04-20 18:10:20,578 - ERROR - Internal Server Error: /login/
Traceback (most recent call last):
  File "/Users/sergionvte/Documents/Modular/venv/lib/python3.9/site-packages/django/core/handlers/exception.py", line 55, in inner
    response = get_response(request)
  File "/Users/sergionvte/Documents/Modular/venv/lib/python3.9/site-packages/django/core/handlers/base.py", line 197, in _get_response
    response = wrapped_callback(request, *callback_args, **callback_kwargs)
  File "/Users/sergionvte/Documents/Modular/moviematch/webapp/views.py", line 50, in user_login
    return render(request, 'login.html', {'form': form})
  File "/Users/sergionvte/Documents/Modular/venv/lib/python3.9/site-packages/django/shortcuts.py", line 24, in render
    content = loader.render_to_string(template_name, context, request, using=using)
  File "/Users/sergionvte/Documents/Modular/venv/lib/python3.9/site-packages/django/template/loader.py", line 61, in render_to_string
    template = get_template(template_name, using=using)
  File "/Users/sergionvte/Documents/Modular/venv/lib/python3.9/site-packages/django/template/loader.py", line 19, in get_template
    raise TemplateDoesNotExist(template_name, chain=chain)
django.template.exceptions.TemplateDoesNotExist: login.html
2024-04-20 18:10:33,681 - INFO - /Users/sergionvte/Documents/Modular/moviematch/webapp/views.py changed, reloading.
2024-04-20 18:11:15,944 - INFO - /Users/sergionvte/Documents/Modular/moviematch/webapp/views.py changed, reloading.
2024-04-20 18:11:42,907 - INFO - /Users/sergionvte/Documents/Modular/moviematch/webapp/views.py changed, reloading.
2024-04-20 18:12:03,631 - INFO - /Users/sergionvte/Documents/Modular/moviematch/webapp/views.py changed, reloading.
2024-04-20 18:20:31,847 - INFO - /Users/sergionvte/Documents/Modular/moviematch/webapp/admin.py changed, reloading.
2024-04-20 18:25:00,952 - INFO - /Users/sergionvte/Documents/Modular/moviematch/webapp/views.py changed, reloading.
2024-04-20 18:26:44,792 - INFO - /Users/sergionvte/Documents/Modular/moviematch/webapp/views.py changed, reloading.
2024-04-20 18:27:40,408 - INFO - /Users/sergionvte/Documents/Modular/moviematch/webapp/models.py changed, reloading.
2024-04-20 18:28:01,207 - INFO - /Users/sergionvte/Documents/Modular/moviematch/webapp/views.py changed, reloading.
2024-04-20 18:28:23,026 - INFO - /Users/sergionvte/Documents/Modular/moviematch/webapp/views.py changed, reloading.
2024-04-20 18:30:59,744 - INFO - /Users/sergionvte/Documents/Modular/moviematch/webapp/views.py changed, reloading.
2024-04-20 18:32:48,649 - INFO - /Users/sergionvte/Documents/Modular/moviematch/webapp/views.py changed, reloading.
2024-04-20 18:33:01,552 - ERROR - Internal Server Error: /login/
Traceback (most recent call last):
  File "/Users/sergionvte/Documents/Modular/venv/lib/python3.9/site-packages/django/core/handlers/exception.py", line 55, in inner
    response = get_response(request)
  File "/Users/sergionvte/Documents/Modular/venv/lib/python3.9/site-packages/django/core/handlers/base.py", line 197, in _get_response
    response = wrapped_callback(request, *callback_args, **callback_kwargs)
  File "/Users/sergionvte/Documents/Modular/moviematch/webapp/views.py", line 25, in user_login
    return render(request, 'auth/login.html', {'form': form})
NameError: name 'form' is not defined
2024-04-20 18:34:18,195 - INFO - /Users/sergionvte/Documents/Modular/moviematch/webapp/models.py changed, reloading.
2024-04-20 18:36:06,005 - INFO - /Users/sergionvte/Documents/Modular/moviematch/webapp/views.py changed, reloading.
2024-04-20 18:37:47,923 - INFO - /Users/sergionvte/Documents/Modular/moviematch/webapp/views.py changed, reloading.
2024-04-20 18:41:02,754 - INFO - /Users/sergionvte/Documents/Modular/moviematch/webapp/views.py changed, reloading.
2024-06-01 17:43:18,982 - INFO - /Users/sergionvte/Documents/Modular/moviematch/webapp/models.py changed, reloading.
2024-06-01 17:43:32,647 - INFO - /Users/sergionvte/Documents/Modular/moviematch/webapp/models.py changed, reloading.
2024-06-01 17:51:46,867 - INFO - /Users/sergionvte/Documents/Modular/moviematch/webapp/models.py changed, reloading.
2024-06-01 17:52:57,792 - INFO - /Users/sergionvte/Documents/Modular/moviematch/webapp/models.py changed, reloading.
2024-06-01 18:06:18,931 - INFO - /Users/sergionvte/Documents/Modular/moviematch/webapp/views.py changed, reloading.
2024-06-01 18:06:54,044 - INFO - /Users/sergionvte/Documents/Modular/moviematch/webapp/views.py changed, reloading.
2024-06-01 18:14:48,931 - INFO - /Users/sergionvte/Documents/Modular/moviematch/webapp/models.py changed, reloading.
2024-06-01 18:14:58,435 - INFO - /Users/sergionvte/Documents/Modular/moviematch/webapp/models.py changed, reloading.
2024-06-01 18:15:34,411 - INFO - /Users/sergionvte/Documents/Modular/moviematch/moviematch/settings.py changed, reloading.
2024-06-01 18:15:35,576 - ERROR - Internal Server Error: /login/
Traceback (most recent call last):
  File "/Users/sergionvte/Documents/Modular/venv/lib/python3.9/site-packages/django/db/backends/utils.py", line 89, in _execute
    return self.cursor.execute(sql, params)
  File "/Users/sergionvte/Documents/Modular/venv/lib/python3.9/site-packages/django/db/backends/mysql/base.py", line 75, in execute
    return self.cursor.execute(query, args)
  File "/Users/sergionvte/Documents/Modular/venv/lib/python3.9/site-packages/MySQLdb/cursors.py", line 179, in execute
    res = self._query(mogrified_query)
  File "/Users/sergionvte/Documents/Modular/venv/lib/python3.9/site-packages/MySQLdb/cursors.py", line 330, in _query
    db.query(q)
  File "/Users/sergionvte/Documents/Modular/venv/lib/python3.9/site-packages/MySQLdb/connections.py", line 261, in query
    _mysql.connection.query(self, query)
MySQLdb.OperationalError: (1054, "Unknown column 'webapp_user.last_login' in 'field list'")

The above exception was the direct cause of the following exception:

Traceback (most recent call last):
  File "/Users/sergionvte/Documents/Modular/venv/lib/python3.9/site-packages/django/core/handlers/exception.py", line 55, in inner
    response = get_response(request)
  File "/Users/sergionvte/Documents/Modular/venv/lib/python3.9/site-packages/django/core/handlers/base.py", line 197, in _get_response
    response = wrapped_callback(request, *callback_args, **callback_kwargs)
  File "/Users/sergionvte/Documents/Modular/venv/lib/python3.9/site-packages/django/utils/decorators.py", line 134, in _wrapper_view
    response = view_func(request, *args, **kwargs)
  File "/Users/sergionvte/Documents/Modular/moviematch/webapp/views.py", line 33, in user_login
    user = authenticate(request, username=email, password=password)
  File "/Users/sergionvte/Documents/Modular/venv/lib/python3.9/site-packages/django/views/decorators/debug.py", line 42, in sensitive_variables_wrapper
    return func(*func_args, **func_kwargs)
  File "/Users/sergionvte/Documents/Modular/venv/lib/python3.9/site-packages/django/contrib/auth/__init__.py", line 77, in authenticate
    user = backend.authenticate(request, **credentials)
  File "/Users/sergionvte/Documents/Modular/venv/lib/python3.9/site-packages/django/contrib/auth/backends.py", line 46, in authenticate
    user = UserModel._default_manager.get_by_natural_key(username)
  File "/Users/sergionvte/Documents/Modular/venv/lib/python3.9/site-packages/django/contrib/auth/base_user.py", line 54, in get_by_natural_key
    return self.get(**{self.model.USERNAME_FIELD: username})
  File "/Users/sergionvte/Documents/Modular/venv/lib/python3.9/site-packages/django/db/models/manager.py", line 87, in manager_method
    return getattr(self.get_queryset(), name)(*args, **kwargs)
  File "/Users/sergionvte/Documents/Modular/venv/lib/python3.9/site-packages/django/db/models/query.py", line 633, in get
    num = len(clone)
  File "/Users/sergionvte/Documents/Modular/venv/lib/python3.9/site-packages/django/db/models/query.py", line 380, in __len__
    self._fetch_all()
  File "/Users/sergionvte/Documents/Modular/venv/lib/python3.9/site-packages/django/db/models/query.py", line 1881, in _fetch_all
    self._result_cache = list(self._iterable_class(self))
  File "/Users/sergionvte/Documents/Modular/venv/lib/python3.9/site-packages/django/db/models/query.py", line 91, in __iter__
    results = compiler.execute_sql(
  File "/Users/sergionvte/Documents/Modular/venv/lib/python3.9/site-packages/django/db/models/sql/compiler.py", line 1562, in execute_sql
    cursor.execute(sql, params)
  File "/Users/sergionvte/Documents/Modular/venv/lib/python3.9/site-packages/django/db/backends/utils.py", line 102, in execute
    return super().execute(sql, params)
  File "/Users/sergionvte/Documents/Modular/venv/lib/python3.9/site-packages/django/db/backends/utils.py", line 67, in execute
    return self._execute_with_wrappers(
  File "/Users/sergionvte/Documents/Modular/venv/lib/python3.9/site-packages/django/db/backends/utils.py", line 80, in _execute_with_wrappers
    return executor(sql, params, many, context)
  File "/Users/sergionvte/Documents/Modular/venv/lib/python3.9/site-packages/django/db/backends/utils.py", line 89, in _execute
    return self.cursor.execute(sql, params)
  File "/Users/sergionvte/Documents/Modular/venv/lib/python3.9/site-packages/django/db/utils.py", line 91, in __exit__
    raise dj_exc_value.with_traceback(traceback) from exc_value
  File "/Users/sergionvte/Documents/Modular/venv/lib/python3.9/site-packages/django/db/backends/utils.py", line 89, in _execute
    return self.cursor.execute(sql, params)
  File "/Users/sergionvte/Documents/Modular/venv/lib/python3.9/site-packages/django/db/backends/mysql/base.py", line 75, in execute
    return self.cursor.execute(query, args)
  File "/Users/sergionvte/Documents/Modular/venv/lib/python3.9/site-packages/MySQLdb/cursors.py", line 179, in execute
    res = self._query(mogrified_query)
  File "/Users/sergionvte/Documents/Modular/venv/lib/python3.9/site-packages/MySQLdb/cursors.py", line 330, in _query
    db.query(q)
  File "/Users/sergionvte/Documents/Modular/venv/lib/python3.9/site-packages/MySQLdb/connections.py", line 261, in query
    _mysql.connection.query(self, query)
django.db.utils.OperationalError: (1054, "Unknown column 'webapp_user.last_login' in 'field list'")
2024-06-01 18:15:35,667 - WARNING - Not Found: /favicon.ico
2024-06-01 18:15:42,888 - INFO - /Users/sergionvte/Documents/Modular/moviematch/moviematch/settings.py changed, reloading.
2024-06-01 18:15:43,175 - ERROR - Internal Server Error: /login/
Traceback (most recent call last):
  File "/Users/sergionvte/Documents/Modular/venv/lib/python3.9/site-packages/django/db/backends/utils.py", line 89, in _execute
    return self.cursor.execute(sql, params)
  File "/Users/sergionvte/Documents/Modular/venv/lib/python3.9/site-packages/django/db/backends/mysql/base.py", line 75, in execute
    return self.cursor.execute(query, args)
  File "/Users/sergionvte/Documents/Modular/venv/lib/python3.9/site-packages/MySQLdb/cursors.py", line 179, in execute
    res = self._query(mogrified_query)
  File "/Users/sergionvte/Documents/Modular/venv/lib/python3.9/site-packages/MySQLdb/cursors.py", line 330, in _query
    db.query(q)
  File "/Users/sergionvte/Documents/Modular/venv/lib/python3.9/site-packages/MySQLdb/connections.py", line 261, in query
    _mysql.connection.query(self, query)
MySQLdb.OperationalError: (1054, "Unknown column 'webapp_user.last_login' in 'field list'")

The above exception was the direct cause of the following exception:

Traceback (most recent call last):
  File "/Users/sergionvte/Documents/Modular/venv/lib/python3.9/site-packages/django/core/handlers/exception.py", line 55, in inner
    response = get_response(request)
  File "/Users/sergionvte/Documents/Modular/venv/lib/python3.9/site-packages/django/core/handlers/base.py", line 197, in _get_response
    response = wrapped_callback(request, *callback_args, **callback_kwargs)
  File "/Users/sergionvte/Documents/Modular/venv/lib/python3.9/site-packages/django/utils/decorators.py", line 134, in _wrapper_view
    response = view_func(request, *args, **kwargs)
  File "/Users/sergionvte/Documents/Modular/moviematch/webapp/views.py", line 33, in user_login
    user = authenticate(request, username=email, password=password)
  File "/Users/sergionvte/Documents/Modular/venv/lib/python3.9/site-packages/django/views/decorators/debug.py", line 42, in sensitive_variables_wrapper
    return func(*func_args, **func_kwargs)
  File "/Users/sergionvte/Documents/Modular/venv/lib/python3.9/site-packages/django/contrib/auth/__init__.py", line 77, in authenticate
    user = backend.authenticate(request, **credentials)
  File "/Users/sergionvte/Documents/Modular/venv/lib/python3.9/site-packages/django/contrib/auth/backends.py", line 46, in authenticate
    user = UserModel._default_manager.get_by_natural_key(username)
  File "/Users/sergionvte/Documents/Modular/venv/lib/python3.9/site-packages/django/contrib/auth/base_user.py", line 54, in get_by_natural_key
    return self.get(**{self.model.USERNAME_FIELD: username})
  File "/Users/sergionvte/Documents/Modular/venv/lib/python3.9/site-packages/django/db/models/manager.py", line 87, in manager_method
    return getattr(self.get_queryset(), name)(*args, **kwargs)
  File "/Users/sergionvte/Documents/Modular/venv/lib/python3.9/site-packages/django/db/models/query.py", line 633, in get
    num = len(clone)
  File "/Users/sergionvte/Documents/Modular/venv/lib/python3.9/site-packages/django/db/models/query.py", line 380, in __len__
    self._fetch_all()
  File "/Users/sergionvte/Documents/Modular/venv/lib/python3.9/site-packages/django/db/models/query.py", line 1881, in _fetch_all
    self._result_cache = list(self._iterable_class(self))
  File "/Users/sergionvte/Documents/Modular/venv/lib/python3.9/site-packages/django/db/models/query.py", line 91, in __iter__
    results = compiler.execute_sql(
  File "/Users/sergionvte/Documents/Modular/venv/lib/python3.9/site-packages/django/db/models/sql/compiler.py", line 1562, in execute_sql
    cursor.execute(sql, params)
  File "/Users/sergionvte/Documents/Modular/venv/lib/python3.9/site-packages/django/db/backends/utils.py", line 102, in execute
    return super().execute(sql, params)
  File "/Users/sergionvte/Documents/Modular/venv/lib/python3.9/site-packages/django/db/backends/utils.py", line 67, in execute
    return self._execute_with_wrappers(
  File "/Users/sergionvte/Documents/Modular/venv/lib/python3.9/site-packages/django/db/backends/utils.py", line 80, in _execute_with_wrappers
    return executor(sql, params, many, context)
  File "/Users/sergionvte/Documents/Modular/venv/lib/python3.9/site-packages/django/db/backends/utils.py", line 89, in _execute
    return self.cursor.execute(sql, params)
  File "/Users/sergionvte/Documents/Modular/venv/lib/python3.9/site-packages/django/db/utils.py", line 91, in __exit__
    raise dj_exc_value.with_traceback(traceback) from exc_value
  File "/Users/sergionvte/Documents/Modular/venv/lib/python3.9/site-packages/django/db/backends/utils.py", line 89, in _execute
    return self.cursor.execute(sql, params)
  File "/Users/sergionvte/Documents/Modular/venv/lib/python3.9/site-packages/django/db/backends/mysql/base.py", line 75, in execute
    return self.cursor.execute(query, args)
  File "/Users/sergionvte/Documents/Modular/venv/lib/python3.9/site-packages/MySQLdb/cursors.py", line 179, in execute
    res = self._query(mogrified_query)
  File "/Users/sergionvte/Documents/Modular/venv/lib/python3.9/site-packages/MySQLdb/cursors.py", line 330, in _query
    db.query(q)
  File "/Users/sergionvte/Documents/Modular/venv/lib/python3.9/site-packages/MySQLdb/connections.py", line 261, in query
    _mysql.connection.query(self, query)
django.db.utils.OperationalError: (1054, "Unknown column 'webapp_user.last_login' in 'field list'")
2024-06-01 18:16:38,302 - INFO - /Users/sergionvte/Documents/Modular/moviematch/webapp/views.py changed, reloading.
2024-06-01 18:16:38,696 - INFO - Correo: asdffg@gmail.com, Contraseña: 123
2024-06-01 18:16:38,734 - ERROR - Internal Server Error: /login/
Traceback (most recent call last):
  File "/Users/sergionvte/Documents/Modular/venv/lib/python3.9/site-packages/django/db/backends/utils.py", line 89, in _execute
    return self.cursor.execute(sql, params)
  File "/Users/sergionvte/Documents/Modular/venv/lib/python3.9/site-packages/django/db/backends/mysql/base.py", line 75, in execute
    return self.cursor.execute(query, args)
  File "/Users/sergionvte/Documents/Modular/venv/lib/python3.9/site-packages/MySQLdb/cursors.py", line 179, in execute
    res = self._query(mogrified_query)
  File "/Users/sergionvte/Documents/Modular/venv/lib/python3.9/site-packages/MySQLdb/cursors.py", line 330, in _query
    db.query(q)
  File "/Users/sergionvte/Documents/Modular/venv/lib/python3.9/site-packages/MySQLdb/connections.py", line 261, in query
    _mysql.connection.query(self, query)
MySQLdb.OperationalError: (1054, "Unknown column 'webapp_user.last_login' in 'field list'")

The above exception was the direct cause of the following exception:

Traceback (most recent call last):
  File "/Users/sergionvte/Documents/Modular/venv/lib/python3.9/site-packages/django/core/handlers/exception.py", line 55, in inner
    response = get_response(request)
  File "/Users/sergionvte/Documents/Modular/venv/lib/python3.9/site-packages/django/core/handlers/base.py", line 197, in _get_response
    response = wrapped_callback(request, *callback_args, **callback_kwargs)
  File "/Users/sergionvte/Documents/Modular/venv/lib/python3.9/site-packages/django/utils/decorators.py", line 134, in _wrapper_view
    response = view_func(request, *args, **kwargs)
  File "/Users/sergionvte/Documents/Modular/moviematch/webapp/views.py", line 46, in user_login
    user = authenticate(request, email=email, password=password)
  File "/Users/sergionvte/Documents/Modular/venv/lib/python3.9/site-packages/django/views/decorators/debug.py", line 42, in sensitive_variables_wrapper
    return func(*func_args, **func_kwargs)
  File "/Users/sergionvte/Documents/Modular/venv/lib/python3.9/site-packages/django/contrib/auth/__init__.py", line 77, in authenticate
    user = backend.authenticate(request, **credentials)
  File "/Users/sergionvte/Documents/Modular/venv/lib/python3.9/site-packages/django/contrib/auth/backends.py", line 46, in authenticate
    user = UserModel._default_manager.get_by_natural_key(username)
  File "/Users/sergionvte/Documents/Modular/venv/lib/python3.9/site-packages/django/contrib/auth/base_user.py", line 54, in get_by_natural_key
    return self.get(**{self.model.USERNAME_FIELD: username})
  File "/Users/sergionvte/Documents/Modular/venv/lib/python3.9/site-packages/django/db/models/manager.py", line 87, in manager_method
    return getattr(self.get_queryset(), name)(*args, **kwargs)
  File "/Users/sergionvte/Documents/Modular/venv/lib/python3.9/site-packages/django/db/models/query.py", line 633, in get
    num = len(clone)
  File "/Users/sergionvte/Documents/Modular/venv/lib/python3.9/site-packages/django/db/models/query.py", line 380, in __len__
    self._fetch_all()
  File "/Users/sergionvte/Documents/Modular/venv/lib/python3.9/site-packages/django/db/models/query.py", line 1881, in _fetch_all
    self._result_cache = list(self._iterable_class(self))
  File "/Users/sergionvte/Documents/Modular/venv/lib/python3.9/site-packages/django/db/models/query.py", line 91, in __iter__
    results = compiler.execute_sql(
  File "/Users/sergionvte/Documents/Modular/venv/lib/python3.9/site-packages/django/db/models/sql/compiler.py", line 1562, in execute_sql
    cursor.execute(sql, params)
  File "/Users/sergionvte/Documents/Modular/venv/lib/python3.9/site-packages/django/db/backends/utils.py", line 102, in execute
    return super().execute(sql, params)
  File "/Users/sergionvte/Documents/Modular/venv/lib/python3.9/site-packages/django/db/backends/utils.py", line 67, in execute
    return self._execute_with_wrappers(
  File "/Users/sergionvte/Documents/Modular/venv/lib/python3.9/site-packages/django/db/backends/utils.py", line 80, in _execute_with_wrappers
    return executor(sql, params, many, context)
  File "/Users/sergionvte/Documents/Modular/venv/lib/python3.9/site-packages/django/db/backends/utils.py", line 89, in _execute
    return self.cursor.execute(sql, params)
  File "/Users/sergionvte/Documents/Modular/venv/lib/python3.9/site-packages/django/db/utils.py", line 91, in __exit__
    raise dj_exc_value.with_traceback(traceback) from exc_value
  File "/Users/sergionvte/Documents/Modular/venv/lib/python3.9/site-packages/django/db/backends/utils.py", line 89, in _execute
    return self.cursor.execute(sql, params)
  File "/Users/sergionvte/Documents/Modular/venv/lib/python3.9/site-packages/django/db/backends/mysql/base.py", line 75, in execute
    return self.cursor.execute(query, args)
  File "/Users/sergionvte/Documents/Modular/venv/lib/python3.9/site-packages/MySQLdb/cursors.py", line 179, in execute
    res = self._query(mogrified_query)
  File "/Users/sergionvte/Documents/Modular/venv/lib/python3.9/site-packages/MySQLdb/cursors.py", line 330, in _query
    db.query(q)
  File "/Users/sergionvte/Documents/Modular/venv/lib/python3.9/site-packages/MySQLdb/connections.py", line 261, in query
    _mysql.connection.query(self, query)
django.db.utils.OperationalError: (1054, "Unknown column 'webapp_user.last_login' in 'field list'")
2024-06-01 18:17:23,710 - INFO - Correo: asdffg@gmail.com, Contraseña: 123
2024-06-01 18:17:23,759 - ERROR - Internal Server Error: /login/
Traceback (most recent call last):
  File "/Users/sergionvte/Documents/Modular/venv/lib/python3.9/site-packages/django/db/backends/utils.py", line 89, in _execute
    return self.cursor.execute(sql, params)
  File "/Users/sergionvte/Documents/Modular/venv/lib/python3.9/site-packages/django/db/backends/mysql/base.py", line 75, in execute
    return self.cursor.execute(query, args)
  File "/Users/sergionvte/Documents/Modular/venv/lib/python3.9/site-packages/MySQLdb/cursors.py", line 179, in execute
    res = self._query(mogrified_query)
  File "/Users/sergionvte/Documents/Modular/venv/lib/python3.9/site-packages/MySQLdb/cursors.py", line 330, in _query
    db.query(q)
  File "/Users/sergionvte/Documents/Modular/venv/lib/python3.9/site-packages/MySQLdb/connections.py", line 261, in query
    _mysql.connection.query(self, query)
MySQLdb.OperationalError: (1054, "Unknown column 'webapp_user.last_login' in 'field list'")

The above exception was the direct cause of the following exception:

Traceback (most recent call last):
  File "/Users/sergionvte/Documents/Modular/venv/lib/python3.9/site-packages/django/core/handlers/exception.py", line 55, in inner
    response = get_response(request)
  File "/Users/sergionvte/Documents/Modular/venv/lib/python3.9/site-packages/django/core/handlers/base.py", line 197, in _get_response
    response = wrapped_callback(request, *callback_args, **callback_kwargs)
  File "/Users/sergionvte/Documents/Modular/venv/lib/python3.9/site-packages/django/utils/decorators.py", line 134, in _wrapper_view
    response = view_func(request, *args, **kwargs)
  File "/Users/sergionvte/Documents/Modular/moviematch/webapp/views.py", line 46, in user_login
    user = authenticate(request, email=email, password=password)
  File "/Users/sergionvte/Documents/Modular/venv/lib/python3.9/site-packages/django/views/decorators/debug.py", line 42, in sensitive_variables_wrapper
    return func(*func_args, **func_kwargs)
  File "/Users/sergionvte/Documents/Modular/venv/lib/python3.9/site-packages/django/contrib/auth/__init__.py", line 77, in authenticate
    user = backend.authenticate(request, **credentials)
  File "/Users/sergionvte/Documents/Modular/venv/lib/python3.9/site-packages/django/contrib/auth/backends.py", line 46, in authenticate
    user = UserModel._default_manager.get_by_natural_key(username)
  File "/Users/sergionvte/Documents/Modular/venv/lib/python3.9/site-packages/django/contrib/auth/base_user.py", line 54, in get_by_natural_key
    return self.get(**{self.model.USERNAME_FIELD: username})
  File "/Users/sergionvte/Documents/Modular/venv/lib/python3.9/site-packages/django/db/models/manager.py", line 87, in manager_method
    return getattr(self.get_queryset(), name)(*args, **kwargs)
  File "/Users/sergionvte/Documents/Modular/venv/lib/python3.9/site-packages/django/db/models/query.py", line 633, in get
    num = len(clone)
  File "/Users/sergionvte/Documents/Modular/venv/lib/python3.9/site-packages/django/db/models/query.py", line 380, in __len__
    self._fetch_all()
  File "/Users/sergionvte/Documents/Modular/venv/lib/python3.9/site-packages/django/db/models/query.py", line 1881, in _fetch_all
    self._result_cache = list(self._iterable_class(self))
  File "/Users/sergionvte/Documents/Modular/venv/lib/python3.9/site-packages/django/db/models/query.py", line 91, in __iter__
    results = compiler.execute_sql(
  File "/Users/sergionvte/Documents/Modular/venv/lib/python3.9/site-packages/django/db/models/sql/compiler.py", line 1562, in execute_sql
    cursor.execute(sql, params)
  File "/Users/sergionvte/Documents/Modular/venv/lib/python3.9/site-packages/django/db/backends/utils.py", line 102, in execute
    return super().execute(sql, params)
  File "/Users/sergionvte/Documents/Modular/venv/lib/python3.9/site-packages/django/db/backends/utils.py", line 67, in execute
    return self._execute_with_wrappers(
  File "/Users/sergionvte/Documents/Modular/venv/lib/python3.9/site-packages/django/db/backends/utils.py", line 80, in _execute_with_wrappers
    return executor(sql, params, many, context)
  File "/Users/sergionvte/Documents/Modular/venv/lib/python3.9/site-packages/django/db/backends/utils.py", line 89, in _execute
    return self.cursor.execute(sql, params)
  File "/Users/sergionvte/Documents/Modular/venv/lib/python3.9/site-packages/django/db/utils.py", line 91, in __exit__
    raise dj_exc_value.with_traceback(traceback) from exc_value
  File "/Users/sergionvte/Documents/Modular/venv/lib/python3.9/site-packages/django/db/backends/utils.py", line 89, in _execute
    return self.cursor.execute(sql, params)
  File "/Users/sergionvte/Documents/Modular/venv/lib/python3.9/site-packages/django/db/backends/mysql/base.py", line 75, in execute
    return self.cursor.execute(query, args)
  File "/Users/sergionvte/Documents/Modular/venv/lib/python3.9/site-packages/MySQLdb/cursors.py", line 179, in execute
    res = self._query(mogrified_query)
  File "/Users/sergionvte/Documents/Modular/venv/lib/python3.9/site-packages/MySQLdb/cursors.py", line 330, in _query
    db.query(q)
  File "/Users/sergionvte/Documents/Modular/venv/lib/python3.9/site-packages/MySQLdb/connections.py", line 261, in query
    _mysql.connection.query(self, query)
django.db.utils.OperationalError: (1054, "Unknown column 'webapp_user.last_login' in 'field list'")
2024-06-01 18:17:27,811 - INFO - Correo: asdffg@gmail.com, Contraseña: 123
2024-06-01 18:17:27,856 - ERROR - Internal Server Error: /login/
Traceback (most recent call last):
  File "/Users/sergionvte/Documents/Modular/venv/lib/python3.9/site-packages/django/db/backends/utils.py", line 89, in _execute
    return self.cursor.execute(sql, params)
  File "/Users/sergionvte/Documents/Modular/venv/lib/python3.9/site-packages/django/db/backends/mysql/base.py", line 75, in execute
    return self.cursor.execute(query, args)
  File "/Users/sergionvte/Documents/Modular/venv/lib/python3.9/site-packages/MySQLdb/cursors.py", line 179, in execute
    res = self._query(mogrified_query)
  File "/Users/sergionvte/Documents/Modular/venv/lib/python3.9/site-packages/MySQLdb/cursors.py", line 330, in _query
    db.query(q)
  File "/Users/sergionvte/Documents/Modular/venv/lib/python3.9/site-packages/MySQLdb/connections.py", line 261, in query
    _mysql.connection.query(self, query)
MySQLdb.OperationalError: (1054, "Unknown column 'webapp_user.last_login' in 'field list'")

The above exception was the direct cause of the following exception:

Traceback (most recent call last):
  File "/Users/sergionvte/Documents/Modular/venv/lib/python3.9/site-packages/django/core/handlers/exception.py", line 55, in inner
    response = get_response(request)
  File "/Users/sergionvte/Documents/Modular/venv/lib/python3.9/site-packages/django/core/handlers/base.py", line 197, in _get_response
    response = wrapped_callback(request, *callback_args, **callback_kwargs)
  File "/Users/sergionvte/Documents/Modular/venv/lib/python3.9/site-packages/django/utils/decorators.py", line 134, in _wrapper_view
    response = view_func(request, *args, **kwargs)
  File "/Users/sergionvte/Documents/Modular/moviematch/webapp/views.py", line 46, in user_login
    user = authenticate(request, email=email, password=password)
  File "/Users/sergionvte/Documents/Modular/venv/lib/python3.9/site-packages/django/views/decorators/debug.py", line 42, in sensitive_variables_wrapper
    return func(*func_args, **func_kwargs)
  File "/Users/sergionvte/Documents/Modular/venv/lib/python3.9/site-packages/django/contrib/auth/__init__.py", line 77, in authenticate
    user = backend.authenticate(request, **credentials)
  File "/Users/sergionvte/Documents/Modular/venv/lib/python3.9/site-packages/django/contrib/auth/backends.py", line 46, in authenticate
    user = UserModel._default_manager.get_by_natural_key(username)
  File "/Users/sergionvte/Documents/Modular/venv/lib/python3.9/site-packages/django/contrib/auth/base_user.py", line 54, in get_by_natural_key
    return self.get(**{self.model.USERNAME_FIELD: username})
  File "/Users/sergionvte/Documents/Modular/venv/lib/python3.9/site-packages/django/db/models/manager.py", line 87, in manager_method
    return getattr(self.get_queryset(), name)(*args, **kwargs)
  File "/Users/sergionvte/Documents/Modular/venv/lib/python3.9/site-packages/django/db/models/query.py", line 633, in get
    num = len(clone)
  File "/Users/sergionvte/Documents/Modular/venv/lib/python3.9/site-packages/django/db/models/query.py", line 380, in __len__
    self._fetch_all()
  File "/Users/sergionvte/Documents/Modular/venv/lib/python3.9/site-packages/django/db/models/query.py", line 1881, in _fetch_all
    self._result_cache = list(self._iterable_class(self))
  File "/Users/sergionvte/Documents/Modular/venv/lib/python3.9/site-packages/django/db/models/query.py", line 91, in __iter__
    results = compiler.execute_sql(
  File "/Users/sergionvte/Documents/Modular/venv/lib/python3.9/site-packages/django/db/models/sql/compiler.py", line 1562, in execute_sql
    cursor.execute(sql, params)
  File "/Users/sergionvte/Documents/Modular/venv/lib/python3.9/site-packages/django/db/backends/utils.py", line 102, in execute
    return super().execute(sql, params)
  File "/Users/sergionvte/Documents/Modular/venv/lib/python3.9/site-packages/django/db/backends/utils.py", line 67, in execute
    return self._execute_with_wrappers(
  File "/Users/sergionvte/Documents/Modular/venv/lib/python3.9/site-packages/django/db/backends/utils.py", line 80, in _execute_with_wrappers
    return executor(sql, params, many, context)
  File "/Users/sergionvte/Documents/Modular/venv/lib/python3.9/site-packages/django/db/backends/utils.py", line 89, in _execute
    return self.cursor.execute(sql, params)
  File "/Users/sergionvte/Documents/Modular/venv/lib/python3.9/site-packages/django/db/utils.py", line 91, in __exit__
    raise dj_exc_value.with_traceback(traceback) from exc_value
  File "/Users/sergionvte/Documents/Modular/venv/lib/python3.9/site-packages/django/db/backends/utils.py", line 89, in _execute
    return self.cursor.execute(sql, params)
  File "/Users/sergionvte/Documents/Modular/venv/lib/python3.9/site-packages/django/db/backends/mysql/base.py", line 75, in execute
    return self.cursor.execute(query, args)
  File "/Users/sergionvte/Documents/Modular/venv/lib/python3.9/site-packages/MySQLdb/cursors.py", line 179, in execute
    res = self._query(mogrified_query)
  File "/Users/sergionvte/Documents/Modular/venv/lib/python3.9/site-packages/MySQLdb/cursors.py", line 330, in _query
    db.query(q)
  File "/Users/sergionvte/Documents/Modular/venv/lib/python3.9/site-packages/MySQLdb/connections.py", line 261, in query
    _mysql.connection.query(self, query)
django.db.utils.OperationalError: (1054, "Unknown column 'webapp_user.last_login' in 'field list'")
2024-06-01 18:17:28,818 - INFO - Correo: asdffg@gmail.com, Contraseña: 123
2024-06-01 18:17:28,838 - ERROR - Internal Server Error: /login/
Traceback (most recent call last):
  File "/Users/sergionvte/Documents/Modular/venv/lib/python3.9/site-packages/django/db/backends/utils.py", line 89, in _execute
    return self.cursor.execute(sql, params)
  File "/Users/sergionvte/Documents/Modular/venv/lib/python3.9/site-packages/django/db/backends/mysql/base.py", line 75, in execute
    return self.cursor.execute(query, args)
  File "/Users/sergionvte/Documents/Modular/venv/lib/python3.9/site-packages/MySQLdb/cursors.py", line 179, in execute
    res = self._query(mogrified_query)
  File "/Users/sergionvte/Documents/Modular/venv/lib/python3.9/site-packages/MySQLdb/cursors.py", line 330, in _query
    db.query(q)
  File "/Users/sergionvte/Documents/Modular/venv/lib/python3.9/site-packages/MySQLdb/connections.py", line 261, in query
    _mysql.connection.query(self, query)
MySQLdb.OperationalError: (1054, "Unknown column 'webapp_user.last_login' in 'field list'")

The above exception was the direct cause of the following exception:

Traceback (most recent call last):
  File "/Users/sergionvte/Documents/Modular/venv/lib/python3.9/site-packages/django/core/handlers/exception.py", line 55, in inner
    response = get_response(request)
  File "/Users/sergionvte/Documents/Modular/venv/lib/python3.9/site-packages/django/core/handlers/base.py", line 197, in _get_response
    response = wrapped_callback(request, *callback_args, **callback_kwargs)
  File "/Users/sergionvte/Documents/Modular/venv/lib/python3.9/site-packages/django/utils/decorators.py", line 134, in _wrapper_view
    response = view_func(request, *args, **kwargs)
  File "/Users/sergionvte/Documents/Modular/moviematch/webapp/views.py", line 46, in user_login
    user = authenticate(request, email=email, password=password)
  File "/Users/sergionvte/Documents/Modular/venv/lib/python3.9/site-packages/django/views/decorators/debug.py", line 42, in sensitive_variables_wrapper
    return func(*func_args, **func_kwargs)
  File "/Users/sergionvte/Documents/Modular/venv/lib/python3.9/site-packages/django/contrib/auth/__init__.py", line 77, in authenticate
    user = backend.authenticate(request, **credentials)
  File "/Users/sergionvte/Documents/Modular/venv/lib/python3.9/site-packages/django/contrib/auth/backends.py", line 46, in authenticate
    user = UserModel._default_manager.get_by_natural_key(username)
  File "/Users/sergionvte/Documents/Modular/venv/lib/python3.9/site-packages/django/contrib/auth/base_user.py", line 54, in get_by_natural_key
    return self.get(**{self.model.USERNAME_FIELD: username})
  File "/Users/sergionvte/Documents/Modular/venv/lib/python3.9/site-packages/django/db/models/manager.py", line 87, in manager_method
    return getattr(self.get_queryset(), name)(*args, **kwargs)
  File "/Users/sergionvte/Documents/Modular/venv/lib/python3.9/site-packages/django/db/models/query.py", line 633, in get
    num = len(clone)
  File "/Users/sergionvte/Documents/Modular/venv/lib/python3.9/site-packages/django/db/models/query.py", line 380, in __len__
    self._fetch_all()
  File "/Users/sergionvte/Documents/Modular/venv/lib/python3.9/site-packages/django/db/models/query.py", line 1881, in _fetch_all
    self._result_cache = list(self._iterable_class(self))
  File "/Users/sergionvte/Documents/Modular/venv/lib/python3.9/site-packages/django/db/models/query.py", line 91, in __iter__
    results = compiler.execute_sql(
  File "/Users/sergionvte/Documents/Modular/venv/lib/python3.9/site-packages/django/db/models/sql/compiler.py", line 1562, in execute_sql
    cursor.execute(sql, params)
  File "/Users/sergionvte/Documents/Modular/venv/lib/python3.9/site-packages/django/db/backends/utils.py", line 102, in execute
    return super().execute(sql, params)
  File "/Users/sergionvte/Documents/Modular/venv/lib/python3.9/site-packages/django/db/backends/utils.py", line 67, in execute
    return self._execute_with_wrappers(
  File "/Users/sergionvte/Documents/Modular/venv/lib/python3.9/site-packages/django/db/backends/utils.py", line 80, in _execute_with_wrappers
    return executor(sql, params, many, context)
  File "/Users/sergionvte/Documents/Modular/venv/lib/python3.9/site-packages/django/db/backends/utils.py", line 89, in _execute
    return self.cursor.execute(sql, params)
  File "/Users/sergionvte/Documents/Modular/venv/lib/python3.9/site-packages/django/db/utils.py", line 91, in __exit__
    raise dj_exc_value.with_traceback(traceback) from exc_value
  File "/Users/sergionvte/Documents/Modular/venv/lib/python3.9/site-packages/django/db/backends/utils.py", line 89, in _execute
    return self.cursor.execute(sql, params)
  File "/Users/sergionvte/Documents/Modular/venv/lib/python3.9/site-packages/django/db/backends/mysql/base.py", line 75, in execute
    return self.cursor.execute(query, args)
  File "/Users/sergionvte/Documents/Modular/venv/lib/python3.9/site-packages/MySQLdb/cursors.py", line 179, in execute
    res = self._query(mogrified_query)
  File "/Users/sergionvte/Documents/Modular/venv/lib/python3.9/site-packages/MySQLdb/cursors.py", line 330, in _query
    db.query(q)
  File "/Users/sergionvte/Documents/Modular/venv/lib/python3.9/site-packages/MySQLdb/connections.py", line 261, in query
    _mysql.connection.query(self, query)
django.db.utils.OperationalError: (1054, "Unknown column 'webapp_user.last_login' in 'field list'")
2024-06-01 18:17:38,019 - INFO - Correo: asdffg@gmail.com, Contraseña: 123
2024-06-01 18:17:38,065 - ERROR - Internal Server Error: /login/
Traceback (most recent call last):
  File "/Users/sergionvte/Documents/Modular/venv/lib/python3.9/site-packages/django/db/backends/utils.py", line 89, in _execute
    return self.cursor.execute(sql, params)
  File "/Users/sergionvte/Documents/Modular/venv/lib/python3.9/site-packages/django/db/backends/mysql/base.py", line 75, in execute
    return self.cursor.execute(query, args)
  File "/Users/sergionvte/Documents/Modular/venv/lib/python3.9/site-packages/MySQLdb/cursors.py", line 179, in execute
    res = self._query(mogrified_query)
  File "/Users/sergionvte/Documents/Modular/venv/lib/python3.9/site-packages/MySQLdb/cursors.py", line 330, in _query
    db.query(q)
  File "/Users/sergionvte/Documents/Modular/venv/lib/python3.9/site-packages/MySQLdb/connections.py", line 261, in query
    _mysql.connection.query(self, query)
MySQLdb.OperationalError: (1054, "Unknown column 'webapp_user.last_login' in 'field list'")

The above exception was the direct cause of the following exception:

Traceback (most recent call last):
  File "/Users/sergionvte/Documents/Modular/venv/lib/python3.9/site-packages/django/core/handlers/exception.py", line 55, in inner
    response = get_response(request)
  File "/Users/sergionvte/Documents/Modular/venv/lib/python3.9/site-packages/django/core/handlers/base.py", line 197, in _get_response
    response = wrapped_callback(request, *callback_args, **callback_kwargs)
  File "/Users/sergionvte/Documents/Modular/venv/lib/python3.9/site-packages/django/utils/decorators.py", line 134, in _wrapper_view
    response = view_func(request, *args, **kwargs)
  File "/Users/sergionvte/Documents/Modular/moviematch/webapp/views.py", line 46, in user_login
    user = authenticate(request, email=email, password=password)
  File "/Users/sergionvte/Documents/Modular/venv/lib/python3.9/site-packages/django/views/decorators/debug.py", line 42, in sensitive_variables_wrapper
    return func(*func_args, **func_kwargs)
  File "/Users/sergionvte/Documents/Modular/venv/lib/python3.9/site-packages/django/contrib/auth/__init__.py", line 77, in authenticate
    user = backend.authenticate(request, **credentials)
  File "/Users/sergionvte/Documents/Modular/venv/lib/python3.9/site-packages/django/contrib/auth/backends.py", line 46, in authenticate
    user = UserModel._default_manager.get_by_natural_key(username)
  File "/Users/sergionvte/Documents/Modular/venv/lib/python3.9/site-packages/django/contrib/auth/base_user.py", line 54, in get_by_natural_key
    return self.get(**{self.model.USERNAME_FIELD: username})
  File "/Users/sergionvte/Documents/Modular/venv/lib/python3.9/site-packages/django/db/models/manager.py", line 87, in manager_method
    return getattr(self.get_queryset(), name)(*args, **kwargs)
  File "/Users/sergionvte/Documents/Modular/venv/lib/python3.9/site-packages/django/db/models/query.py", line 633, in get
    num = len(clone)
  File "/Users/sergionvte/Documents/Modular/venv/lib/python3.9/site-packages/django/db/models/query.py", line 380, in __len__
    self._fetch_all()
  File "/Users/sergionvte/Documents/Modular/venv/lib/python3.9/site-packages/django/db/models/query.py", line 1881, in _fetch_all
    self._result_cache = list(self._iterable_class(self))
  File "/Users/sergionvte/Documents/Modular/venv/lib/python3.9/site-packages/django/db/models/query.py", line 91, in __iter__
    results = compiler.execute_sql(
  File "/Users/sergionvte/Documents/Modular/venv/lib/python3.9/site-packages/django/db/models/sql/compiler.py", line 1562, in execute_sql
    cursor.execute(sql, params)
  File "/Users/sergionvte/Documents/Modular/venv/lib/python3.9/site-packages/django/db/backends/utils.py", line 102, in execute
    return super().execute(sql, params)
  File "/Users/sergionvte/Documents/Modular/venv/lib/python3.9/site-packages/django/db/backends/utils.py", line 67, in execute
    return self._execute_with_wrappers(
  File "/Users/sergionvte/Documents/Modular/venv/lib/python3.9/site-packages/django/db/backends/utils.py", line 80, in _execute_with_wrappers
    return executor(sql, params, many, context)
  File "/Users/sergionvte/Documents/Modular/venv/lib/python3.9/site-packages/django/db/backends/utils.py", line 89, in _execute
    return self.cursor.execute(sql, params)
  File "/Users/sergionvte/Documents/Modular/venv/lib/python3.9/site-packages/django/db/utils.py", line 91, in __exit__
    raise dj_exc_value.with_traceback(traceback) from exc_value
  File "/Users/sergionvte/Documents/Modular/venv/lib/python3.9/site-packages/django/db/backends/utils.py", line 89, in _execute
    return self.cursor.execute(sql, params)
  File "/Users/sergionvte/Documents/Modular/venv/lib/python3.9/site-packages/django/db/backends/mysql/base.py", line 75, in execute
    return self.cursor.execute(query, args)
  File "/Users/sergionvte/Documents/Modular/venv/lib/python3.9/site-packages/MySQLdb/cursors.py", line 179, in execute
    res = self._query(mogrified_query)
  File "/Users/sergionvte/Documents/Modular/venv/lib/python3.9/site-packages/MySQLdb/cursors.py", line 330, in _query
    db.query(q)
  File "/Users/sergionvte/Documents/Modular/venv/lib/python3.9/site-packages/MySQLdb/connections.py", line 261, in query
    _mysql.connection.query(self, query)
django.db.utils.OperationalError: (1054, "Unknown column 'webapp_user.last_login' in 'field list'")
2024-06-01 18:17:58,446 - INFO - Correo: asdffg@gmail.com, Contraseña: 123
2024-06-01 18:17:58,477 - ERROR - Internal Server Error: /login/
Traceback (most recent call last):
  File "/Users/sergionvte/Documents/Modular/venv/lib/python3.9/site-packages/django/db/backends/utils.py", line 89, in _execute
    return self.cursor.execute(sql, params)
  File "/Users/sergionvte/Documents/Modular/venv/lib/python3.9/site-packages/django/db/backends/mysql/base.py", line 75, in execute
    return self.cursor.execute(query, args)
  File "/Users/sergionvte/Documents/Modular/venv/lib/python3.9/site-packages/MySQLdb/cursors.py", line 179, in execute
    res = self._query(mogrified_query)
  File "/Users/sergionvte/Documents/Modular/venv/lib/python3.9/site-packages/MySQLdb/cursors.py", line 330, in _query
    db.query(q)
  File "/Users/sergionvte/Documents/Modular/venv/lib/python3.9/site-packages/MySQLdb/connections.py", line 261, in query
    _mysql.connection.query(self, query)
MySQLdb.OperationalError: (1054, "Unknown column 'webapp_user.last_login' in 'field list'")

The above exception was the direct cause of the following exception:

Traceback (most recent call last):
  File "/Users/sergionvte/Documents/Modular/venv/lib/python3.9/site-packages/django/core/handlers/exception.py", line 55, in inner
    response = get_response(request)
  File "/Users/sergionvte/Documents/Modular/venv/lib/python3.9/site-packages/django/core/handlers/base.py", line 197, in _get_response
    response = wrapped_callback(request, *callback_args, **callback_kwargs)
  File "/Users/sergionvte/Documents/Modular/venv/lib/python3.9/site-packages/django/utils/decorators.py", line 134, in _wrapper_view
    response = view_func(request, *args, **kwargs)
  File "/Users/sergionvte/Documents/Modular/moviematch/webapp/views.py", line 46, in user_login
    user = authenticate(request, email=email, password=password)
  File "/Users/sergionvte/Documents/Modular/venv/lib/python3.9/site-packages/django/views/decorators/debug.py", line 42, in sensitive_variables_wrapper
    return func(*func_args, **func_kwargs)
  File "/Users/sergionvte/Documents/Modular/venv/lib/python3.9/site-packages/django/contrib/auth/__init__.py", line 77, in authenticate
    user = backend.authenticate(request, **credentials)
  File "/Users/sergionvte/Documents/Modular/venv/lib/python3.9/site-packages/django/contrib/auth/backends.py", line 46, in authenticate
    user = UserModel._default_manager.get_by_natural_key(username)
  File "/Users/sergionvte/Documents/Modular/venv/lib/python3.9/site-packages/django/contrib/auth/base_user.py", line 54, in get_by_natural_key
    return self.get(**{self.model.USERNAME_FIELD: username})
  File "/Users/sergionvte/Documents/Modular/venv/lib/python3.9/site-packages/django/db/models/manager.py", line 87, in manager_method
    return getattr(self.get_queryset(), name)(*args, **kwargs)
  File "/Users/sergionvte/Documents/Modular/venv/lib/python3.9/site-packages/django/db/models/query.py", line 633, in get
    num = len(clone)
  File "/Users/sergionvte/Documents/Modular/venv/lib/python3.9/site-packages/django/db/models/query.py", line 380, in __len__
    self._fetch_all()
  File "/Users/sergionvte/Documents/Modular/venv/lib/python3.9/site-packages/django/db/models/query.py", line 1881, in _fetch_all
    self._result_cache = list(self._iterable_class(self))
  File "/Users/sergionvte/Documents/Modular/venv/lib/python3.9/site-packages/django/db/models/query.py", line 91, in __iter__
    results = compiler.execute_sql(
  File "/Users/sergionvte/Documents/Modular/venv/lib/python3.9/site-packages/django/db/models/sql/compiler.py", line 1562, in execute_sql
    cursor.execute(sql, params)
  File "/Users/sergionvte/Documents/Modular/venv/lib/python3.9/site-packages/django/db/backends/utils.py", line 102, in execute
    return super().execute(sql, params)
  File "/Users/sergionvte/Documents/Modular/venv/lib/python3.9/site-packages/django/db/backends/utils.py", line 67, in execute
    return self._execute_with_wrappers(
  File "/Users/sergionvte/Documents/Modular/venv/lib/python3.9/site-packages/django/db/backends/utils.py", line 80, in _execute_with_wrappers
    return executor(sql, params, many, context)
  File "/Users/sergionvte/Documents/Modular/venv/lib/python3.9/site-packages/django/db/backends/utils.py", line 89, in _execute
    return self.cursor.execute(sql, params)
  File "/Users/sergionvte/Documents/Modular/venv/lib/python3.9/site-packages/django/db/utils.py", line 91, in __exit__
    raise dj_exc_value.with_traceback(traceback) from exc_value
  File "/Users/sergionvte/Documents/Modular/venv/lib/python3.9/site-packages/django/db/backends/utils.py", line 89, in _execute
    return self.cursor.execute(sql, params)
  File "/Users/sergionvte/Documents/Modular/venv/lib/python3.9/site-packages/django/db/backends/mysql/base.py", line 75, in execute
    return self.cursor.execute(query, args)
  File "/Users/sergionvte/Documents/Modular/venv/lib/python3.9/site-packages/MySQLdb/cursors.py", line 179, in execute
    res = self._query(mogrified_query)
  File "/Users/sergionvte/Documents/Modular/venv/lib/python3.9/site-packages/MySQLdb/cursors.py", line 330, in _query
    db.query(q)
  File "/Users/sergionvte/Documents/Modular/venv/lib/python3.9/site-packages/MySQLdb/connections.py", line 261, in query
    _mysql.connection.query(self, query)
django.db.utils.OperationalError: (1054, "Unknown column 'webapp_user.last_login' in 'field list'")
2024-06-01 18:27:37,345 - INFO - /Users/sergionvte/Documents/Modular/moviematch/moviematch/settings.py changed, reloading.
2024-06-01 18:27:37,729 - INFO - Correo: asdffg@gmail.com, Contraseña: 123
2024-06-01 18:27:37,748 - ERROR - Credenciales inválidas. Inténtalo de nuevo.
2024-06-01 18:32:59,875 - INFO - /Users/sergionvte/Documents/Modular/moviematch/webapp/views.py changed, reloading.
2024-06-01 18:33:03,369 - INFO - Correo: asdffg@gmail.com, Contraseña: 123
2024-06-01 18:33:03,576 - ERROR - Credenciales inválidas. Inténtalo de nuevo.
2024-06-01 18:34:00,661 - INFO - Correo: sergionvte11@gmail.com, Contraseña: 1234
2024-06-01 18:34:00,881 - INFO - Usuario autenticado correctamente: sergionvte11@gmail.com
2024-06-01 18:34:33,496 - INFO - /Users/sergionvte/Documents/Modular/moviematch/webapp/views.py changed, reloading.
2024-06-01 18:34:44,846 - INFO - Correo: sergionvte11@gmail.com, Contraseña: 1234
2024-06-01 18:34:45,073 - INFO - Usuario autenticado correctamente: sergionvte11@gmail.com
2024-06-01 18:36:06,715 - INFO - /Users/sergionvte/Documents/Modular/moviematch/webapp/views.py changed, reloading.
2024-06-01 18:36:18,243 - INFO - /Users/sergionvte/Documents/Modular/moviematch/webapp/views.py changed, reloading.
2024-06-01 18:39:32,965 - INFO - /Users/sergionvte/Documents/Modular/moviematch/webapp/views.py changed, reloading.
2024-06-01 18:41:01,201 - INFO - /Users/sergionvte/Documents/Modular/moviematch/moviematch/urls.py changed, reloading.
2024-06-01 18:41:07,729 - INFO - /Users/sergionvte/Documents/Modular/moviematch/moviematch/urls.py changed, reloading.
2024-06-01 18:41:49,976 - INFO - /Users/sergionvte/Documents/Modular/moviematch/webapp/views.py changed, reloading.
2024-06-01 18:42:34,167 - INFO - /Users/sergionvte/Documents/Modular/moviematch/moviematch/urls.py changed, reloading.
2024-06-01 18:42:43,706 - INFO - /Users/sergionvte/Documents/Modular/moviematch/webapp/views.py changed, reloading.
2024-06-01 18:42:48,601 - ERROR - Internal Server Error: /logout/
Traceback (most recent call last):
  File "/Users/sergionvte/Documents/Modular/venv/lib/python3.9/site-packages/django/core/handlers/exception.py", line 55, in inner
    response = get_response(request)
  File "/Users/sergionvte/Documents/Modular/venv/lib/python3.9/site-packages/django/core/handlers/base.py", line 197, in _get_response
    response = wrapped_callback(request, *callback_args, **callback_kwargs)
  File "/Users/sergionvte/Documents/Modular/moviematch/webapp/views.py", line 94, in logout
    logout(request)
  File "/Users/sergionvte/Documents/Modular/moviematch/webapp/views.py", line 94, in logout
    logout(request)
  File "/Users/sergionvte/Documents/Modular/moviematch/webapp/views.py", line 94, in logout
    logout(request)
  [Previous line repeated 956 more times]
RecursionError: maximum recursion depth exceeded
2024-06-01 18:43:38,283 - INFO - /Users/sergionvte/Documents/Modular/moviematch/webapp/views.py changed, reloading.
2024-06-01 18:43:47,418 - INFO - Correo: sergionvte11@gmail.com, Contraseña: 1234
2024-06-01 18:43:47,641 - INFO - Usuario autenticado correctamente: sergionvte11@gmail.com
2024-06-01 18:44:56,402 - INFO - /Users/sergionvte/Documents/Modular/moviematch/moviematch/settings.py changed, reloading.
2024-06-01 18:50:07,480 - INFO - Correo: sergionvte11@gmail.com, Contraseña: 1234
2024-06-01 18:50:07,817 - INFO - Usuario autenticado correctamente: sergionvte11@gmail.com
2024-06-01 18:50:19,144 - INFO - Correo: sergionvte11@gmail.com, Contraseña: 121212
2024-06-01 18:50:19,350 - ERROR - Credenciales inválidas. Inténtalo de nuevo.
2024-06-01 18:52:31,104 - INFO - /Users/sergionvte/Documents/Modular/moviematch/webapp/models.py changed, reloading.
2024-06-01 18:54:01,665 - INFO - /Users/sergionvte/Documents/Modular/moviematch/webapp/models.py changed, reloading.
2024-06-01 19:37:54,405 - INFO - /Users/sergionvte/Documents/Modular/moviematch/webapp/views.py changed, reloading.
2024-06-01 19:38:07,046 - INFO - /Users/sergionvte/Documents/Modular/moviematch/webapp/views.py changed, reloading.
2024-06-01 19:39:19,918 - INFO - /Users/sergionvte/Documents/Modular/moviematch/webapp/views.py changed, reloading.
2024-06-01 19:40:16,429 - INFO - /Users/sergionvte/Documents/Modular/moviematch/webapp/views.py changed, reloading.
2024-06-01 19:40:22,810 - INFO - /Users/sergionvte/Documents/Modular/moviematch/webapp/views.py changed, reloading.
2024-06-01 19:41:32,580 - INFO - Correo: sergionvte11@gmail.com, Contraseña: 1234
2024-06-01 19:41:32,856 - INFO - Usuario autenticado correctamente: sergionvte11@gmail.com
2024-06-01 19:41:54,263 - WARNING - Not Found: /productos/
2024-06-01 19:41:56,651 - WARNING - Not Found: /dashboard
2024-06-01 19:42:49,217 - WARNING - Not Found: /dashboard
2024-06-01 19:42:54,735 - ERROR - Internal Server Error: /
Traceback (most recent call last):
  File "/Users/sergionvte/Documents/Modular/venv/lib/python3.9/site-packages/django/core/handlers/exception.py", line 55, in inner
    response = get_response(request)
  File "/Users/sergionvte/Documents/Modular/venv/lib/python3.9/site-packages/django/core/handlers/base.py", line 197, in _get_response
    response = wrapped_callback(request, *callback_args, **callback_kwargs)
  File "/Users/sergionvte/Documents/Modular/moviematch/webapp/views.py", line 46, in index
    return render(request, 'index.html', context)
  File "/Users/sergionvte/Documents/Modular/venv/lib/python3.9/site-packages/django/shortcuts.py", line 24, in render
    content = loader.render_to_string(template_name, context, request, using=using)
  File "/Users/sergionvte/Documents/Modular/venv/lib/python3.9/site-packages/django/template/loader.py", line 61, in render_to_string
    template = get_template(template_name, using=using)
  File "/Users/sergionvte/Documents/Modular/venv/lib/python3.9/site-packages/django/template/loader.py", line 15, in get_template
    return engine.get_template(template_name)
  File "/Users/sergionvte/Documents/Modular/venv/lib/python3.9/site-packages/django/template/backends/django.py", line 33, in get_template
    return Template(self.engine.get_template(template_name), self)
  File "/Users/sergionvte/Documents/Modular/venv/lib/python3.9/site-packages/django/template/engine.py", line 175, in get_template
    template, origin = self.find_template(template_name)
  File "/Users/sergionvte/Documents/Modular/venv/lib/python3.9/site-packages/django/template/engine.py", line 157, in find_template
    template = loader.get_template(name, skip=skip)
  File "/Users/sergionvte/Documents/Modular/venv/lib/python3.9/site-packages/django/template/loaders/cached.py", line 57, in get_template
    template = super().get_template(template_name, skip)
  File "/Users/sergionvte/Documents/Modular/venv/lib/python3.9/site-packages/django/template/loaders/base.py", line 28, in get_template
    return Template(
  File "/Users/sergionvte/Documents/Modular/venv/lib/python3.9/site-packages/django/template/base.py", line 154, in __init__
    self.nodelist = self.compile_nodelist()
  File "/Users/sergionvte/Documents/Modular/venv/lib/python3.9/site-packages/django/template/base.py", line 200, in compile_nodelist
    return parser.parse()
  File "/Users/sergionvte/Documents/Modular/venv/lib/python3.9/site-packages/django/template/base.py", line 513, in parse
    raise self.error(token, e)
  File "/Users/sergionvte/Documents/Modular/venv/lib/python3.9/site-packages/django/template/base.py", line 511, in parse
    compiled_result = compile_func(self, token)
  File "/Users/sergionvte/Documents/Modular/venv/lib/python3.9/site-packages/django/template/loader_tags.py", line 293, in do_extends
    nodelist = parser.parse()
  File "/Users/sergionvte/Documents/Modular/venv/lib/python3.9/site-packages/django/template/base.py", line 513, in parse
    raise self.error(token, e)
  File "/Users/sergionvte/Documents/Modular/venv/lib/python3.9/site-packages/django/template/base.py", line 511, in parse
    compiled_result = compile_func(self, token)
  File "/Users/sergionvte/Documents/Modular/venv/lib/python3.9/site-packages/django/template/loader_tags.py", line 232, in do_block
    nodelist = parser.parse(("endblock",))
  File "/Users/sergionvte/Documents/Modular/venv/lib/python3.9/site-packages/django/template/base.py", line 513, in parse
    raise self.error(token, e)
  File "/Users/sergionvte/Documents/Modular/venv/lib/python3.9/site-packages/django/template/base.py", line 511, in parse
    compiled_result = compile_func(self, token)
  File "/Users/sergionvte/Documents/Modular/venv/lib/python3.9/site-packages/django/template/defaulttags.py", line 953, in do_if
    nodelist = parser.parse(("elif", "else", "endif"))
  File "/Users/sergionvte/Documents/Modular/venv/lib/python3.9/site-packages/django/template/base.py", line 513, in parse
    raise self.error(token, e)
  File "/Users/sergionvte/Documents/Modular/venv/lib/python3.9/site-packages/django/template/base.py", line 511, in parse
    compiled_result = compile_func(self, token)
  File "/Users/sergionvte/Documents/Modular/venv/lib/python3.9/site-packages/django/template/loader_tags.py", line 349, in do_include
    parser.compile_filter(bits[1]),
  File "/Users/sergionvte/Documents/Modular/venv/lib/python3.9/site-packages/django/template/base.py", line 600, in compile_filter
    return FilterExpression(token, self)
  File "/Users/sergionvte/Documents/Modular/venv/lib/python3.9/site-packages/django/template/base.py", line 703, in __init__
    raise TemplateSyntaxError(
django.template.exceptions.TemplateSyntaxError: Could not parse the remainder: ''dashboard.html' from ''dashboard.html'
2024-06-23 16:19:33,983 - ERROR - Internal Server Error: /
Traceback (most recent call last):
  File "/Users/sergionvte/Documents/Modular/venv/lib/python3.9/site-packages/django/core/handlers/exception.py", line 55, in inner
    response = get_response(request)
  File "/Users/sergionvte/Documents/Modular/venv/lib/python3.9/site-packages/django/core/handlers/base.py", line 197, in _get_response
    response = wrapped_callback(request, *callback_args, **callback_kwargs)
  File "/Users/sergionvte/Documents/Modular/moviematch/webapp/views.py", line 46, in index
    return render(request, 'index.html', context)
  File "/Users/sergionvte/Documents/Modular/venv/lib/python3.9/site-packages/django/shortcuts.py", line 24, in render
    content = loader.render_to_string(template_name, context, request, using=using)
  File "/Users/sergionvte/Documents/Modular/venv/lib/python3.9/site-packages/django/template/loader.py", line 61, in render_to_string
    template = get_template(template_name, using=using)
  File "/Users/sergionvte/Documents/Modular/venv/lib/python3.9/site-packages/django/template/loader.py", line 15, in get_template
    return engine.get_template(template_name)
  File "/Users/sergionvte/Documents/Modular/venv/lib/python3.9/site-packages/django/template/backends/django.py", line 33, in get_template
    return Template(self.engine.get_template(template_name), self)
  File "/Users/sergionvte/Documents/Modular/venv/lib/python3.9/site-packages/django/template/engine.py", line 175, in get_template
    template, origin = self.find_template(template_name)
  File "/Users/sergionvte/Documents/Modular/venv/lib/python3.9/site-packages/django/template/engine.py", line 157, in find_template
    template = loader.get_template(name, skip=skip)
  File "/Users/sergionvte/Documents/Modular/venv/lib/python3.9/site-packages/django/template/loaders/cached.py", line 57, in get_template
    template = super().get_template(template_name, skip)
  File "/Users/sergionvte/Documents/Modular/venv/lib/python3.9/site-packages/django/template/loaders/base.py", line 28, in get_template
    return Template(
  File "/Users/sergionvte/Documents/Modular/venv/lib/python3.9/site-packages/django/template/base.py", line 154, in __init__
    self.nodelist = self.compile_nodelist()
  File "/Users/sergionvte/Documents/Modular/venv/lib/python3.9/site-packages/django/template/base.py", line 200, in compile_nodelist
    return parser.parse()
  File "/Users/sergionvte/Documents/Modular/venv/lib/python3.9/site-packages/django/template/base.py", line 513, in parse
    raise self.error(token, e)
  File "/Users/sergionvte/Documents/Modular/venv/lib/python3.9/site-packages/django/template/base.py", line 511, in parse
    compiled_result = compile_func(self, token)
  File "/Users/sergionvte/Documents/Modular/venv/lib/python3.9/site-packages/django/template/loader_tags.py", line 293, in do_extends
    nodelist = parser.parse()
  File "/Users/sergionvte/Documents/Modular/venv/lib/python3.9/site-packages/django/template/base.py", line 513, in parse
    raise self.error(token, e)
  File "/Users/sergionvte/Documents/Modular/venv/lib/python3.9/site-packages/django/template/base.py", line 511, in parse
    compiled_result = compile_func(self, token)
  File "/Users/sergionvte/Documents/Modular/venv/lib/python3.9/site-packages/django/template/loader_tags.py", line 232, in do_block
    nodelist = parser.parse(("endblock",))
  File "/Users/sergionvte/Documents/Modular/venv/lib/python3.9/site-packages/django/template/base.py", line 513, in parse
    raise self.error(token, e)
  File "/Users/sergionvte/Documents/Modular/venv/lib/python3.9/site-packages/django/template/base.py", line 511, in parse
    compiled_result = compile_func(self, token)
  File "/Users/sergionvte/Documents/Modular/venv/lib/python3.9/site-packages/django/template/defaulttags.py", line 953, in do_if
    nodelist = parser.parse(("elif", "else", "endif"))
  File "/Users/sergionvte/Documents/Modular/venv/lib/python3.9/site-packages/django/template/base.py", line 513, in parse
    raise self.error(token, e)
  File "/Users/sergionvte/Documents/Modular/venv/lib/python3.9/site-packages/django/template/base.py", line 511, in parse
    compiled_result = compile_func(self, token)
  File "/Users/sergionvte/Documents/Modular/venv/lib/python3.9/site-packages/django/template/loader_tags.py", line 349, in do_include
    parser.compile_filter(bits[1]),
  File "/Users/sergionvte/Documents/Modular/venv/lib/python3.9/site-packages/django/template/base.py", line 600, in compile_filter
    return FilterExpression(token, self)
  File "/Users/sergionvte/Documents/Modular/venv/lib/python3.9/site-packages/django/template/base.py", line 703, in __init__
    raise TemplateSyntaxError(
django.template.exceptions.TemplateSyntaxError: Could not parse the remainder: ''dashboard.html' from ''dashboard.html'
2024-06-23 16:19:34,107 - WARNING - Not Found: /favicon.ico
